Workbook
Name Beg_Bal: #REF!
Name Chinthi: '[1]P&L'!#REF!
Name Cum_Int: #REF!
Name Data: #REF!
Name End_Bal: #REF!
Name Extra_Pay: #REF!
Name Full_Print: #REF!
Name Header_Row: ROW(#REF!)
Name Int: #REF!
Name Interest_Rate: #REF!
Name Last_Row: IF(Values_Entered,Header_Row+Number_of_Payments,Header_Row)
Name Loan_Amount: #REF!
Name Loan_Start: #REF!
Name Loan_Years: #REF!
Name Num_Pmt_Per_Year: #REF!
Name Number_of_Payments: MATCH(0.01,End_Bal,-1)+1
Name Pay_Date: #REF!
Name Pay_Num: #REF!
Name Payment_Date: DATE(YEAR(Loan_Start),MONTH(Loan_Start)+Payment_Number,DAY(Loan_Start))
Name Princ: #REF!
Name Print_Area_Reset: OFFSET(Full_Print,0,0,Last_Row)
Name ranji: '[1]P&L'!#REF!
Name Sched_Pay: #REF!
Name Scheduled_Extra_Payments: #REF!
Name Scheduled_Interest_Rate: #REF!
Name Scheduled_Monthly_Payment: #REF!
Name Total_Interest: #REF!
Name Total_Pay: #REF!
Name Values_Entered: IF(Loan_Amount*Interest_Rate*Loan_Years*Loan_Start>0,1,0)
Name vDateTime: #REF!
Name vDiastolic: #REF!
Name vHeartRate: #REF!
Name vSystolic: #REF!

Sheet Ref
A1: Check this
A2: Motor Bike | B2: 210000
A3: Insurance | B3: 10500

Sheet PPE
A1: Fixed Asset Register
A3: Asset | B3: Month of purchased | C3: Rate | D3: Amount | E3: Month starting Depreciation | F3: Date | G3: Depreciation Amount
A4: =+Working!A20 -> Furniture & Fittings | B4: 45385 | C4: 5 | D4: =+Working!B20 -> 153700 | E4: 45728 | F4: =E4-B4 -> 343 | G4: =(D4/5)*(F4/365) -> 28887.178
A5: =+Working!A21 -> Office Equipment | B5: 45388 | C5: 5 | D5: =+Working!B21 -> 4600 | E5: 45728 | F5: =E5-B5 -> 340 | G5: =(D5/5)*(F5/365) -> 856.9863
A6: =+Working!A22 -> Computer & Printers | B6: 45410 | C6: 5 | D6: =+Working!B22 -> 35000 | E6: 45728 | F6: =E6-B6 -> 318 | G6: =(D6/5)*(F6/365) -> 6098.6301
A7: =+Working!A23 -> Furniture & Fittings | B7: 45410 | C7: 5 | D7: =+Working!B23 -> 82500 | E7: 45728 | F7: =E7-B7 -> 318 | G7: =(D7/5)*(F7/365) -> 14375.342
A8: =+Working!A24 -> Telephone | B8: 45389 | C8: 5 | D8: =+Working!B24 -> 36340 | E8: 45728 | F8: =E8-B8 -> 339 | G8: =(D8/5)*(F8/365) -> 6750.2795
A9: =+Working!A25 -> CCTV Camera | B9: 45410 | C9: 5 | D9: =+Working!B25 -> 23690 | E9: 45728 | F9: =E9-B9 -> 318 | G9: =(D9/5)*(F9/365) -> 4127.9014
D10: =SUM(D4:D9) -> 335830 | G10: =SUM(G4:G9) -> 61096.318

Sheet Working
A2: Interest Income | B2: 2328236
A4: Expenses
A5: Advertisment & Sales Promotion | B5: 99975
A6: Bad Debts | B6: 163480
A7: Commission | B7: 11000
A8: Salaries & Wages | B8: 900750
A9: EPF & Etf | B9: 16522
A10: Rent | B10: 171150
A11: Maintance & Repair | B11: 71672.5
A12: Electricity | B12: 13070
A13: Phone & Internet bills | B13: 45597
A14: Company Incorporation fees | B14: 60000
A15: Insurance | B15: 10500
A16: Stationery & Documents | B16: 94812
C19: Bill Nu.
A20: Furniture & Fittings | B20: 153700 | C20: 520
A21: Office Equipment | B21: 4600 | C21: 1019
A22: Computer & Printers | B22: 35000 | C22: 1039
A23: Furniture & Fittings | B23: 82500 | C23: 525
A24: Telephone | B24: 36340 | C24: 1020
A25: CCTV Camera | B25: =3990+16500+3200 -> 23690 | C25: 1039
A27: EPF & ETF | B27: EPF20% | C27: EPF12% | D27: ETF3%
A28: 45597 | B28: 4200 | C28: =B28*12/20 -> 2520 | D28: =C28*3/12 -> 630
A29: 45627 | B29: 4200 | C29: =B29*12/20 -> 2520 | D29: =C29*3/12 -> 630
A30: 45658 | B30: 4200 | C30: =B30*12/20 -> 2520 | D30: =C30*3/12 -> 630
A31: 45689 | B31: 4200 | C31: =B31*12/20 -> 2520 | D31: =C31*3/12 -> 630
A32: 45717 | B32: 4200 | C32: =B32*12/20 -> 2520 | D32: =C32*3/12 -> 630
A33: Total | B33: =SUM(B28:B32) -> 21000 | C33: =SUM(C28:C32) -> 12600 | D33: =SUM(D28:D32) -> 3150

Sheet TB
A1: N K R S Lanka Capuital Pvt Ltd
A2: Trial Balance
A3: As at 31st March 2025
B4: Dr | C4: Cr
A5: Bank accounts
A6: Cash | B6: 12560
A8: Assets
A9: Furniture & Fittings | B9: =+PPE!D4 -> 153700
A10: Office Equipment | B10: =+PPE!D5 -> 4600
A11: Computer & Printers | B11: =+PPE!D6 -> 35000
A12: Furniture & Fittings | B12: =+PPE!D7 -> 82500
A13: Telephone | B13: =+PPE!D8 -> 36340
A14: CCTV Camera | B14: =+PPE!D9 -> 23690
A15: Accumalated Deprecion | C15: =+PPE!G10 -> 61096.318
A17: Accountany Fee | C17: =+B47 -> 15000
A18: Audit Fee | C18: =+B48 -> 25000
A19: EPF | C19: =Working!B32 -> 4200
A20: ETF | C20: =Working!D32 -> 630 | E20: =C20*20/3 -> 4200
A22: Share capital | C22: =1000*6 -> 6000
A23: Director C/A - Invetment | C23: 1000000
A26: Receivables | B26: 112919.5
A27: Income | C27: =+Working!B2 -> 2328236
A28: ADMINSTRATION EXPENSES
A29: Salaries & Wages | B29: =Working!B8 -> 900750
A30: Dirtectors remuniration | B30: 1220000
A31: Advertisment & Sales Promotion | B31: =Working!B5 -> 99975
A32: Sales Commission | B32: =Working!B7 -> 11000
A33: Rent Expenses | B33: =Working!B10 -> 171150
A34: EPF | B34: =+Working!C33 -> 12600
A35: ETF | B35: =Working!D33 -> 3150
A36: Repair & Maintance | B36: =Working!B11 -> 71672.5
A37: Incorporation Fees | B37: =Working!B14 -> 60000
A38: Electricity | B38: =Working!B12 -> 13070
A39: Telephone & Internet | B39: =Working!B13 -> 45597
A40: Fuel Expenses
A41: Bad Debts | B41: 163480
A42: Insurance | B42: =+Working!B15 -> 10500
A43: Travelling Charges
A44: Printing & Stationery | B44: =Working!B16 -> 94812
A45: Depreciation | B45: =#REF! -> #REF!
...

Sheet P09
A1: N K R S LANKA CAPITAL (PRIVATE) LIMITED | D1: Page 9
A2: NOTES TO THE FINANCIAL STATEMENTS
A3: FOR THE PERIOD ENDED 31ST MARCH | D3: 2025
D4: Rs. | F4: 31/03/2023
F5: Rs.
A6: 4 | B6: Revenue
B7: Commission Income | D7: =+TB!C27 -> 2328236
D8: =D7 -> 2328236
A10: 5 | B10: Administration Expenses
B11: Director Remuniration | D11: =TB!B30 -> 1220000
B12: Salaries & Wages | D12: =TB!B29 -> 900750
B13: EPF | D13: =TB!B34 -> 12600
B14: ETF | D14: =TB!B35 -> 3150
B15: Incorporation Fee | D15: =+TB!B37 -> 60000
B16: Business Promotion & Marketing Expneses | D16: =+TB!B31+TB!B32 -> 110975
B17: Telephone & Internet | D17: =TB!B39 -> 45597
B18: Electricity | D18: =TB!B38 -> 13070
B19: Office Rent | D19: =TB!B33 -> 171150
B20: Insurance | D20: =TB!B42 -> 10500
B21: Office Repair & Maintance | D21: =TB!B36 -> 71672.5
B22: Depreciation | D22: =TB!B45 -> #REF!
B23: Printing & Stationery | D23: =TB!B44 -> 94812
B24: Accountancy Fee | D24: =+TB!B47 -> 15000
B25: Audit Fee | D25: =+TB!B48 -> 25000
D26: =SUM(D11:D25) -> #REF!
A28: 6 | B28: Finance Cost
B29: Bad Debts | D29: =+TB!B41 -> 163480
D30: =SUM(D29) -> 163480
A32: 7 | B32: Income Tax Expense
B33: Current Tax Expense | D33: =TB!B46 -> 0
D34: =+D33 -> 0
